Workbook
Name \1: #REF!
Name \1: #REF!
Name \1: #REF!
Name \a: #REF!
Name \a: #N/A
Name \a: #REF!
Name \b: #REF!
Name \b: #N/A
Name \b: #REF!
Name \c: #REF!
Name \c: #REF!
Name \d: #REF!
Name \d: #REF!
Name \e: #REF!
Name \e: #REF!
Name \f: #REF!
Name \f: #REF!
Name \g: #REF!
Name \g: #REF!
Name \h: #REF!
Name \h: #REF!
Name \i: #REF!
Name \i: #REF!
Name \j: #REF!
Name \j: #REF!
Name \m: #REF!
Name \m: #REF!
Name \n: #REF!
Name \n: #REF!
Name \p: #REF!
Name \p: #REF!
Name \p: #REF!
Name \q: #REF!
Name \q: #REF!
Name \q: #REF!
Name \r: #REF!
Name \r: #REF!
Name \S: #REF!
Name \s: #REF!
Name \S: #REF!
Name \t: #REF!
Name \t: #REF!
Name \w: #REF!
Name \w: #REF!
Name \w: #REF!
Name \x: #REF!
Name \x: #REF!
Name \y: #REF!
Name \y: #REF!
Name \z: #REF!
Name \z: #REF!
Name _\p: #REF!
Name _\p: #REF!
Name ___________________\a: #REF!
Name ___________________\a: #REF!
Name ___________________\d: #REF!
Name ___________________\d: #REF!
Name ___________________\e: #REF!
Name ___________________\e: #REF!
Name ___________________\i: #REF!

Sheet Cubicacion_General
E1: Sistema de impulsion refino | F1: 3631
E2: Lixiviacion piscina emergencia | F2: 3632 | AK2: Avance Acumulado Fisico | AU2: Avance Cañerias E.D.P
E3: Red Contra Incendio | F3: 6340 | AC3: Según Listado | AD3: MM.CUBICADO | AE3: METROS.CUBICADO | AF3: Avance Fisico | AK3: Acumulado Anterior | AM3: Acumulado Actual | AO3: Acumulado Total | AS3: Avance EDP | AU3: EDP_Acumulado Anterior | AW3: EDP_Acumulado Actual | AY3: EDP_Acumulado Total
AC4: =SUBTOTAL(9,AC6:AC482) -> 8807 | AD4: =SUBTOTAL(9,AD6:AD480) -> 11956815 | AE4: =SUBTOTAL(9,AE6:AE480) -> 11956.815 | AF4: 0.1 | AG4: 0.25 | AH4: 0.55 | AI4: 0.1 | AK4: =SUBTOTAL(9,AK6:AK460) -> 0 | AL4: =SUBTOTAL(9,AL6:AL460) -> 0 | AM4: =SUBTOTAL(9,AM6:AM460) -> 0 | AN4: =SUBTOTAL(9,AN6:AN460) -> 0 | AO4: =SUBTOTAL(9,AO6:AO460) -> 0 | AP4: =SUBTOTAL(9,AP6:AP460) -> 0 | AS4: 0.9 | AT4: 0.1 | AV4: =+SUBTOTAL(9,AV6:AV1269) -> 0 | AZ4: =+SUBTOTAL(9,AZ6:AZ1269) -> 0 | BA4: 3 W L A
B5: N° | C5: Contrato | D5: Item Contrato | E5: Area | F5: Codigo Area | G5: N° P&ID Codelco | H5: Rev | I5: N° Plano | J5: Rev | K5: Nro. Linea | L5: Correlativo | M5: Lamina | N5: DN(inch) | O5: DN(mm) | P5: Clase | Q5: Material | R5: Servicio | S5: Aislación | T5: Desde | U5: Hasta | V5: Densidad del Fluido kg/m3 | W5: Presión | X5: T°C | Y5: Presión Nota (1) | Z5: Temperatura C° | AA5: Fluido de Prueba | AB5: Comentario | AC5: Longitud(mts) | AD5: Longitud mm (Cubicado) | AE5: Longitud Mts (Cubicado) | AF5: Traslado | AG5: Posicionamiento | AH5: Montaje-Pruebas | AI5: Protocolos | AJ5: HH Unitaria | AK5: HH | AL5: Cantidad | AM5: HH | AN5: Cantidad | AO5: HH | AP5: Cantidad | AQ5: Programa Maestro | AR5: N° Protocolo | AS5: Recepcion y Traslado | AT5: Protocolo | AU5: % | AV5: Cantidad | AW5: % | AX5: Cantidad | AY5: % | AZ5: Cantidad | BA5: Recepcion y Traslado | BB5: Fabricacion | BC5: Posicionamiento | BD5: Montaje | BE5: Soportacion | BF5: Protocolo
B6: 1 | C6: CC-403 | E6: Sistema de impulsion refino | F6: =LEFT(K6,4) -> 3631 | G6: 4600027788-03631-201CA-00002 | H6: 0 | K6: 3631-RA-16"-T1-0951-N | L6: 951 | N6: 16" | O6: 400 | P6: T1 | R6: RA | S6: N | T6: Bomba 3631-BVT-001 | U6: 3631-RA-30"-T1-0955-N | V6: 1134 | W6: 5102 | X6: 38 | Y6: 6377.6 | Z6: 20° | AA6: Agua | AC6: 6 | AD6: 7720 | AE6: =AD6/1000 -> 7.72 | AN6: =+AP6-AL6 -> 0 | AP6: =+CONCATENATE(AF6*$AF$4+AG6*$AG$4+AH6*$AH$4+AI6*$AI$4) -> 0 | AQ6: =AP6 -> 0 | AS6: =AH6 -> 0 | AT6: =AI6 -> 0
B7: 2 | C7: CC-403 | E7: Sistema de impulsion refino | F7: =LEFT(K7,4) -> 3631 | G7: 4600027788-03631-201CA-00002 | H7: 0 | K7: 3631-RA-16"-T1-0952-N | L7: 952 | N7: 16" | O7: 400 | P7: T1 | R7: RA | S7: N | T7: Bomba 3631-BVT-002 | U7: 3631-RA-30"-T1-0955-N | V7: 1134 | W7: 5102 | X7: 38 | Y7: 6377.6 | Z7: 20° | AA7: Agua | AC7: 6 | AD7: 7720 | AE7: =AD7/1000 -> 7.72 | AN7: =+AP7-AL7 -> 0 | AP7: =+CONCATENATE(AF7*$AF$4+AG7*$AG$4+AH7*$AH$4+AI7*$AI$4) -> 0 | AQ7: =AP7 -> 0 | AS7: =AH7 -> 0 | AT7: =AI7 -> 0
B8: 3 | C8: CC-403 | E8: Sistema de impulsion refino | F8: =LEFT(K8,4) -> 3631 | G8: 4600027788-03631-201CA-00002 | H8: 0 | K8: 3631-RA-16"-T1-0953-N | L8: 953 | N8: 16" | O8: 400 | P8: T1 | R8: RA | S8: N | T8: Bomba 3631-BVT-003 | U8: 3631-RA-30"-T1-0955-N | V8: 1134 | W8: 5102 | X8: 38 | Y8: 6377.6 | Z8: 20° | AA8: Agua | AC8: 6 | AD8: 7720 | AE8: =AD8/1000 -> 7.72 | AN8: =+AP8-AL8 -> 0 | AP8: =+CONCATENATE(AF8*$AF$4+AG8*$AG$4+AH8*$AH$4+AI8*$AI$4) -> 0 | AQ8: =AP8 -> 0 | AS8: =AH8 -> 0 | AT8: =AI8 -> 0
B9: 4 | C9: CC-403 | E9: Sistema de impulsion refino | F9: =LEFT(K9,4) -> 3631 | G9: 4600027788-03631-201CA-00002 | H9: 0 | K9: 3631-RA-16"-T1-0954-N | L9: 954 | N9: 16" | O9: 400 | P9: T1 | R9: RA | S9: N | T9: Bomba 3631-BVT-004 | U9: 3631-RA-30"-T1-0955-N | V9: 1134 | W9: 5102 | X9: 38 | Y9: 6377.6 | Z9: 20° | AA9: Agua | AC9: 6 | AD9: 7720 | AE9: =AD9/1000 -> 7.72 | AN9: =+AP9-AL9 -> 0 | AP9: =+CONCATENATE(AF9*$AF$4+AG9*$AG$4+AH9*$AH$4+AI9*$AI$4) -> 0 | AQ9: =AP9 -> 0 | AS9: =AH9 -> 0 | AT9: =AI9 -> 0
B10: 5 | C10: CC-403 | E10: Sistema de impulsion refino | F10: =LEFT(K10,4) -> 3631 | G10: 4600027788-03631-201CA-00002 | H10: 0 | I10: 4600027788-03631-502CA-00007 | J10: 0 | K10: 3631-RA-400-H1-0956-N | L10: 956 | M10: 1 | N10: 16" | O10: 400 | P10: H1 | R10: RA | S10: N | T10: 3631-RA-30"-T1-0955-N | U10: Piscina de Reimpulsión OBL | V10: 1134 | W10: 1999 | X10: 20 | Y10: Nota (2) | Z10: 20° | AA10: Agua | AB10: Linea de Drenaje | AC10: 13 | AD10: 11322 | AE10: =AD10/1000 -> 11.322 | AN10: =+AP10-AL10 -> 0 | AP10: =+CONCATENATE(AF10*$AF$4+AG10*$AG$4+AH10*$AH$4+AI10*$AI$4) -> 0 | AQ10: =AP10 -> 0 | AS10: =AH10 -> 0 | AT10: =AI10 -> 0
B11: 6 | C11: CC-403 | E11: Sistema de impulsion refino | F11: =LEFT(K11,4) -> 3631 | G11: 4600027788-03631-201CA-00002 | H11: 0 | K11: 3631-RA-30"-T1-0955-N | L11: 955 | N11: 30" | O11: 760 | P11: T1 | R11: RA | S11: N | T11: Brida Ciega | U11: 3631-RA-710-H1-0956-N | V11: 1134 | W11: 5102 | X11: 38 | Y11: 6377.6 | Z11: 20° | AA11: Agua | AB11: Manifold de Descarga | AC11: 31 | AD11: 15575 | AE11: =AD11/1000 -> 15.575 | AN11: =+AP11-AL11 -> 0 | AP11: =+CONCATENATE(AF11*$AF$4+AG11*$AG$4+AH11*$AH$4+AI11*$AI$4) -> 0 | AQ11: =AP11 -> 0 | AS11: =AH11 -> 0 | AT11: =AI11 -> 0
B12: 7 | C12: CC-403 | E12: Sistema de impulsion refino | F12: =LEFT(K12,4) -> 3631 | G12: 4600027788-03631-201CA-00002 | H12: 0 | K12: 3631-RA-24"-T1-0955-N | L12: 955 | N12: 24" | O12: 630 | P12: T1 | R12: RA | S12: N | T12: Brida Ciega | U12: 3631-RA-710-H1-0956-N | V12: 1134 | W12: 5102 | X12: 38 | Y12: 6377.6 | Z12: 20° | AA12: Agua | AB12: Manifold de Descarga | AC12: - | AD12: 12000 | AE12: =AD12/1000 -> 12 | AN12: =+AP12-AL12 -> 0 | AP12: =+CONCATENATE(AF12*$AF$4+AG12*$AG$4+AH12*$AH$4+AI12*$AI$4) -> 0 | AQ12: =AP12 -> 0 | AS12: =AH12 -> 0 | AT12: =AI12 -> 0
B13: 8 | C13: CC-403 | E13: Sistema de impulsion refino | F13: =LEFT(K13,4) -> 3631 | G13: 4600027788-03631-201CA-00002 | H13: 0 | J13: 0 | K13: 3631-RA-30"-T1-0955-N | L13: 955 | N13: 28" | O13: 710 | P13: T1 | R13: RA | S13: N | T13: Brida Ciega | U13: 3631-RA-710-H1-0956-N | V13: 1134 | W13: 5102 | X13: 38 | Y13: 6377.6 | Z13: 20° | AA13: Agua | AB13: Manifold de Descarga | AC13: - | AD13: 47153 | AE13: =AD13/1000 -> 47.153 | AN13: =+AP13-AL13 -> 0 | AP13: =+CONCATENATE(AF13*$AF$4+AG13*$AG$4+AH13*$AH$4+AI13*$AI$4) -> 0 | AQ13: =AP13 -> 0 | AS13: =AH13 -> 0 | AT13: =AI13 -> 0
B14: 9 | C14: CC-403 | E14: Sistema de impulsion refino | F14: =LEFT(K14,4) -> 3631 | G14: 4600027788-03631-201CA-00002 | H14: 0 | I14: 4600027788-03631-502CA-00003 | J14: 0 | K14: 3631-RA-710-H1-0957-N | L14: 957 | M14: 1 | N14: 28" | O14: 710 | P14: H1 | R14: RA | S14: N | T14: 3631-RA-30"-T1-0955-N | U14: 3631-RA-36"-T1-0958-N Nota (3) | V14: 1134 | W14: 1999 | X14: 20 | Y14: Nota (2) | Z14: 20° | AA14: Agua | AC14: 28 | AD14: 17000 | AE14: =AD14/1000 -> 17 | AN14: =+AP14-AL14 -> 0 | AP14: =+CONCATENATE(AF14*$AF$4+AG14*$AG$4+AH14*$AH$4+AI14*$AI$4) -> 0 | AQ14: =AP14 -> 0 | AS14: =AH14 -> 0 | AT14: =AI14 -> 0
B15: 11 | C15: CC-403 | E15: Sistema de impulsion refino | F15: =LEFT(K15,4) -> 3631 | G15: 4600027788-03631-201CA-00002 | H15: 0 | I15: 4600027788-03631-502CA-00004 | J15: 0 | K15: 3631-RA-710-H1-0957-N | L15: 957 | M15: 2 | N15: 28" | O15: 710 | P15: H1 | R15: RA | S15: N | AD15: 7750 | AE15: =AD15/1000 -> 7.75 | AN15: =+AP15-AL15 -> 0 | AP15: =+CONCATENATE(AF15*$AF$4+AG15*$AG$4+AH15*$AH$4+AI15*$AI$4) -> 0 | AQ15: =AP15 -> 0 | AS15: =AH15 -> 0 | AT15: =AI15 -> 0
B16: 13 | C16: CC-403 | E16: Sistema de impulsion refino | F16: =LEFT(K16,4) -> 3631 | G16: 4600027788-03631-201CA-00002 | H16: 0 | I16: 4600027788-03631-502CA-00005 | J16: 0 | K16: 3631-RA-710-H1-0957-N | L16: 957 | M16: 3 | N16: 24" | O16: 710 | P16: H1 | R16: RA | S16: N | AD16: 3570 | AE16: =AD16/1000 -> 3.57 | AN16: =+AP16-AL16 -> 0 | AP16: =+CONCATENATE(AF16*$AF$4+AG16*$AG$4+AH16*$AH$4+AI16*$AI$4) -> 0 | AQ16: =AP16 -> 0 | AS16: =AH16 -> 0 | AT16: =AI16 -> 0
B17: 15 | C17: CC-403 | E17: Sistema de impulsion refino | F17: =LEFT(K17,4) -> 3631 | I17: 4600027788-03631-502CA-00006 | J17: 0 | K17: 3631-RA-110-H4-0958-N | L17: 958 | M17: 1 | N17: 4" | O17: 110 | P17: H4 | R17: RA | S17: N | AD17: 13149 | AE17: =AD17/1000 -> 13.149 | AN17: =+AP17-AL17 -> 0 | AP17: =+CONCATENATE(AF17*$AF$4+AG17*$AG$4+AH17*$AH$4+AI17*$AI$4) -> 0 | AQ17: =AP17 -> 0 | AS17: =AH17 -> 0 | AT17: =AI17 -> 0
B18: 16 | C18: CC-403 | E18: Sistema de impulsion refino | F18: =LEFT(K18,4) -> 3631 | K18: 3631-RA-500-H3-0958-N | L18: 958 | N18: 20" | O18: 500 | P18: H3 | R18: RA | S18: N | AD18: 550000 | AE18: =AD18/1000 -> 550 | AN18: =+AP18-AL18 -> 0 | AP18: =+CONCATENATE(AF18*$AF$4+AG18*$AG$4+AH18*$AH$4+AI18*$AI$4) -> 0 | AQ18: =AP18 -> 0 | AS18: =AH18 -> 0 | AT18: =AI18 -> 0
B19: 17 | C19: CC-403 | E19: Sistema de impulsion refino | F19: =LEFT(K19,4) -> 3631 | K19: 3631-RA-630-H3-0958-N | L19: 958 | N19: 24" | O19: 630 | P19: H3 | R19: RA | S19: N | AD19: 510000 | AE19: =AD19/1000 -> 510 | AN19: =+AP19-AL19 -> 0 | AP19: =+CONCATENATE(AF19*$AF$4+AG19*$AG$4+AH19*$AH$4+AI19*$AI$4) -> 0 | AQ19: =AP19 -> 0 | AS19: =AH19 -> 0 | AT19: =AI19 -> 0
B20: 18 | C20: CC-403 | E20: Sistema de impulsion refino | F20: =LEFT(K20,4) -> 3631 | K20: 3631-RA-710-H3-0958-N | L20: 958 | N20: 28" | O20: 710 | P20: H3 | R20: RA | S20: N | AD20: 255000 | AE20: =AD20/1000 -> 255 | AN20: =+AP20-AL20 -> 0 | AP20: =+CONCATENATE(AF20*$AF$4+AG20*$AG$4+AH20*$AH$4+AI20*$AI$4) -> 0 | AQ20: =AP20 -> 0 | AS20: =AH20 -> 0 | AT20: =AI20 -> 0
B21: 19 | C21: CC-403 | E21: Sistema de impulsion refino | F21: =LEFT(K21,4) -> 3631 | G21: 4600027788-03631-201CA-00002 | H21: 0 | I21: 4600027788-03631-201CA-00002 | K21: 3631-RA-900-H3-0958-N | L21: 958 | N21: 36" | O21: 900 | P21: H3 | R21: RA | S21: N | T21: Brida Ciega | U21: Brida Ciega | V21: 1134 | W21: 1586 | X21: 25 | Y21: Nota (2) | Z21: 20° | AA21: Agua | AB21: Nota (4) | AC21: 5056 | AD21: 3950000 | AE21: =AD21/1000 -> 3950 | AN21: =+AP21-AL21 -> 0 | AP21: =+CONCATENATE(AF21*$AF$4+AG21*$AG$4+AH21*$AH$4+AI21*$AI$4) -> 0 | AQ21: =AP21 -> 0 | AS21: =AH21 -> 0 | AT21: =AI21 -> 0
B22: 20 | C22: CC-403 | E22: Sistema de impulsion refino | F22: =LEFT(K22,4) -> 3631 | G22: 4600027788-03631-201CA-00002 | H22: 0 | K22: 3631-RA-315-H3-0959-N | L22: 959 | N22: 12" | O22: 315 | P22: H3 | R22: RA | S22: N | T22: 3631-RA-900-H3-0958-N Nota (4) | U22: Sistema de Riego (Fuera del alcance del Proyecto) | V22: 1134 | W22: 1586 | X22: 25 | Y22: Nota (2) | Z22: 20° | AA22: Agua | AC22: 111 | AD22: 111950 | AE22: =AD22/1000 -> 111.95 | AN22: =+AP22-AL22 -> 0 | AP22: =+CONCATENATE(AF22*$AF$4+AG22*$AG$4+AH22*$AH$4+AI22*$AI$4) -> 0 | AQ22: =AP22 -> 0 | AS22: =AH22 -> 0 | AT22: =AI22 -> 0
B23: 21 | C23: CC-403 | E23: Sistema de impulsion refino | F23: =LEFT(K23,4) -> 3631 | G23: 4600027788-03631-201CA-00002 | H23: 0 | K23: 3631-RA-315-H3-0905-N | L23: 905 | N23: 12" | O23: 315 | P23: H3 | R23: RA | S23: N | T23: 3631-RA-710-H3-0958-N Nota (4) | U23: Sistema de Riego (Fuera del alcance del Proyecto) | V23: 1134 | W23: 1586 | X23: 25 | Y23: Nota (2) | Z23: 20° | AA23: Agua | AC23: 192 | AD23: 192050 | AE23: =AD23/1000 -> 192.05 | AN23: =+AP23-AL23 -> 0 | AP23: =+CONCATENATE(AF23*$AF$4+AG23*$AG$4+AH23*$AH$4+AI23*$AI$4) -> 0 | AQ23: =AP23 -> 0 | AS23: =AH23 -> 0 | AT23: =AI23 -> 0
B24: 22 | C24: CC-403 | E24: Sistema de impulsion refino | F24: =LEFT(K24,4) -> 3631 | G24: 4600027788-03631-201CA-00002 | H24: 0 | K24: 3631-RA-315-H3-0906-N | L24: 906 | N24: 12" | O24: 315 | P24: H3 | R24: RA | S24: N | T24: 3631-RA-710-H3-0958-N Nota (4) | U24: Sistema de Riego (Fuera del alcance del Proyecto) | V24: 1134 | W24: 1586 | X24: 25 | Y24: Nota (2) | Z24: 20° | AA24: Agua | AC24: 274 | AD24: 274200 | AE24: =AD24/1000 -> 274.2 | AN24: =+AP24-AL24 -> 0 | AP24: =+CONCATENATE(AF24*$AF$4+AG24*$AG$4+AH24*$AH$4+AI24*$AI$4) -> 0 | AQ24: =AP24 -> 0 | AS24: =AH24 -> 0 | AT24: =AI24 -> 0
B25: 23 | C25: CC-403 | E25: Sistema de impulsion refino | F25: =LEFT(K25,4) -> 3631 | G25: 4600027788-03631-201CA-00002 | H25: 0 | K25: 3631-RA-315-H3-0907-N | L25: 907 | N25: 12" | O25: 315 | P25: H3 | R25: RA | S25: N | T25: 3631-RA-710-H3-0958-N Nota (4) | U25: Sistema de Riego (Fuera del alcance del Proyecto) | V25: 1134 | W25: 1586 | X25: 25 | Y25: Nota (2) | Z25: 20° | AA25: Agua | AC25: 358 | AD25: 361650 | AE25: =AD25/1000 -> 361.65 | AN25: =+AP25-AL25 -> 0 | AP25: =+CONCATENATE(AF25*$AF$4+AG25*$AG$4+AH25*$AH$4+AI25*$AI$4) -> 0 | AQ25: =AP25 -> 0 | AS25: =AH25 -> 0 | AT25: =AI25 -> 0
B26: 24 | C26: CC-403 | E26: Sistema de impulsion refino | F26: =LEFT(K26,4) -> 3631 | G26: 4600027788-03631-201CA-00002 | H26: 0 | K26: 3631-RA-315-H3-0908-N | L26: 908 | N26: 12" | O26: 315 | P26: H3 | R26: RA | S26: N | T26: 3631-RA-630-H3-0958-N Nota (4) | U26: Sistema de Riego (Fuera del alcance del Proyecto) | V26: 1134 | W26: 1586 | X26: 25 | Y26: Nota (2) | Z26: 20° | AA26: Agua | AC26: 440 | AD26: 445100 | AE26: =AD26/1000 -> 445.1 | AN26: =+AP26-AL26 -> 0 | AP26: =+CONCATENATE(AF26*$AF$4+AG26*$AG$4+AH26*$AH$4+AI26*$AI$4) -> 0 | AQ26: =AP26 -> 0 | AS26: =AH26 -> 0 | AT26: =AI26 -> 0
B27: 25 | C27: CC-403 | E27: Sistema de impulsion refino | F27: =LEFT(K27,4) -> 3631 | G27: 4600027788-03631-201CA-00002 | H27: 0 | K27: 3631-RA-315-H3-0909-N | L27: 909 | N27: 12" | O27: 315 | P27: H3 | R27: RA | S27: N | T27: 3631-RA-630-H3-0958-N Nota (4) | U27: Sistema de Riego (Fuera del alcance del Proyecto) | V27: 1134 | W27: 1586 | X27: 25 | Y27: Nota (2) | Z27: 20° | AA27: Agua | AC27: 525 | AD27: 528850 | AE27: =AD27/1000 -> 528.85 | AN27: =+AP27-AL27 -> 0 | AP27: =+CONCATENATE(AF27*$AF$4+AG27*$AG$4+AH27*$AH$4+AI27*$AI$4) -> 0 | AQ27: =AP27 -> 0 | AS27: =AH27 -> 0 | AT27: =AI27 -> 0
B28: 26 | C28: CC-403 | E28: Sistema de impulsion refino | F28: =LEFT(K28,4) -> 3631 | G28: 4600027788-03631-201CA-00002 | H28: 0 | K28: 3631-RA-315-H3-0910-N | L28: 910 | N28: 12" | O28: 315 | P28: H3 | R28: RA | S28: N | T28: 3631-RA-630-H3-0958-N Nota (4) | U28: Sistema de Riego (Fuera del alcance del Proyecto) | V28: 1134 | W28: 1586 | X28: 25 | Y28: Nota (2) | Z28: 20° | AA28: Agua | AC28: 611 | AD28: 612550 | AE28: =AD28/1000 -> 612.55 | AN28: =+AP28-AL28 -> 0 | AP28: =+CONCATENATE(AF28*$AF$4+AG28*$AG$4+AH28*$AH$4+AI28*$AI$4) -> 0 | AQ28: =AP28 -> 0 | AS28: =AH28 -> 0 | AT28: =AI28 -> 0
B29: 27 | C29: CC-403 | E29: Sistema de impulsion refino | F29: =LEFT(K29,4) -> 3631 | G29: 4600027788-03631-201CA-00002 | H29: 0 | K29: 3631-RA-315-H3-0911-N | L29: 911 | N29: 12" | O29: 315 | P29: H3 | R29: RA | S29: N | T29: 3631-RA-500-H3-0958-N Nota (4) | U29: Sistema de Riego (Fuerda del alcance del Proyecto) | V29: 1134 | W29: 1586 | X29: 25 | Y29: Nota (2) | Z29: 20° | AA29: Agua | AC29: 637 | AD29: 697100 | AE29: =AD29/1000 -> 697.1 | AN29: =+AP29-AL29 -> 0 | AP29: =+CONCATENATE(AF29*$AF$4+AG29*$AG$4+AH29*$AH$4+AI29*$AI$4) -> 0 | AQ29: =AP29 -> 0 | AS29: =AH29 -> 0 | AT29: =AI29 -> 0
B30: 28 | C30: CC-403 | E30: Sistema de impulsion refino | F30: =LEFT(K30,4) -> 3631 | G30: 4600027788-03631-201CA-00002 | H30: 0 | K30: 3631-RA-315-H3-0912-N | L30: 912 | N30: 12" | O30: 315 | P30: H3 | R30: RA | S30: N | T30: 3631-RA-500-H3-0958-N Nota (4) | U30: Sistema de Riego (Fuera del alcance del Proyecto) | V30: 1134 | W30: 1586 | X30: 25 | Y30: Nota (2) | Z30: 20° | AA30: Agua | AC30: 507 | AD30: 674150 | AE30: =AD30/1000 -> 674.15 | AN30: =+AP30-AL30 -> 0 | AP30: =+CONCATENATE(AF30*$AF$4+AG30*$AG$4+AH30*$AH$4+AI30*$AI$4) -> 0 | AQ30: =AP30 -> 0 | AS30: =AH30 -> 0 | AT30: =AI30 -> 0
B31: 29 | C31: CC-403 | E31: Lixiviacion piscina emergencia | F31: =LEFT(K31,4) -> 3632 | I31: 4600027788-03632-502CA-00001 | J31: 0 | K31: 3632-RA-14"-T2-0931-N | L31: 931 | M31: 1 | N31: 14" | O31: 355 | P31: T2 | R31: RA | S31: N | AD31: 1275 | AE31: =AD31/1000 -> 1.275 | AN31: =+AP31-AL31 -> 0 | AP31: =+CONCATENATE(AF31*$AF$4+AG31*$AG$4+AH31*$AH$4+AI31*$AI$4) -> 0 | AQ31: =AP31 -> 0 | AS31: =AH31 -> 0 | AT31: =AI31 -> 0
B32: 30 | C32: CC-403 | E32: Lixiviacion piscina emergencia | F32: =LEFT(K32,4) -> 3632 | I32: 4600027788-03632-502CA-00003 | J32: 0 | K32: 3632-RA-14"-T2-0932-N | L32: 932 | M32: 1 | N32: 14" | O32: 355 | P32: T2 | R32: RA | S32: N | AD32: 1275 | AE32: =AD32/1000 -> 1.275 | AN32: =+AP32-AL32 -> 0 | AP32: =+CONCATENATE(AF32*$AF$4+AG32*$AG$4+AH32*$AH$4+AI32*$AI$4) -> 0 | AQ32: =AP32 -> 0 | AS32: =AH32 -> 0 | AT32: =AI32 -> 0
B33: 31 | C33: CC-403 | E33: Lixiviacion piscina emergencia | F33: =LEFT(K33,4) -> 3632 | I33: 4600027788-03632-102CA-00002/00004/00005 | J33: 0 | K33: 3632-RA-355-H4-0933-N | L33: 933 | N33: 14" | O33: 355 | P33: H4 | AD33: 350000 | AE33: =AD33/1000 -> 350 | AN33: =+AP33-AL33 -> 0 | AP33: =+CONCATENATE(AF33*$AF$4+AG33*$AG$4+AH33*$AH$4+AI33*$AI$4) -> 0 | AQ33: =AP33 -> 0 | AS33: =AH33 -> 0 | AT33: =AI33 -> 0
B34: 32 | C34: CC-403 | E34: Lixiviacion piscina emergencia | F34: =LEFT(K34,4) -> 3632 | I34: 4600027788-03632-502CA-00002 | J34: 0 | K34: 3632-RA-355-H4-0933-N | L34: 933 | M34: 1 | N34: 14" | O34: 355 | P34: H4 | R34: RA | S34: N | AD34: 2658 | AE34: =AD34/1000 -> 2.658 | AN34: =+AP34-AL34 -> 0 | AP34: =+CONCATENATE(AF34*$AF$4+AG34*$AG$4+AH34*$AH$4+AI34*$AI$4) -> 0 | AQ34: =AP34 -> 0 | AS34: =AH34 -> 0 | AT34: =AI34 -> 0
B35: 33 | C35: CC-403 | E35: Lixiviacion piscina emergencia | F35: =LEFT(K35,4) -> 3632 | I35: 4600027788-03632-502CA-00004 | J35: 0 | K35: 3632-RA-355-H4-0933-N | L35: 933 | M35: 2 | N35: 14" | O35: 355 | P35: H4 | R35: RA | S35: N | AD35: 2658 | AE35: =AD35/1000 -> 2.658 | AN35: =+AP35-AL35 -> 0 | AP35: =+CONCATENATE(AF35*$AF$4+AG35*$AG$4+AH35*$AH$4+AI35*$AI$4) -> 0 | AQ35: =AP35 -> 0 | AS35: =AH35 -> 0 | AT35: =AI35 -> 0
B36: 34 | C36: CC-403 | E36: Lixiviacion piscina emergencia | F36: =LEFT(K36,4) -> 3632 | I36: 4600027788-03632-502CA-00005 | J36: 0 | K36: 3632-RA-355-H4-0933-N | L36: 933 | M36: 3 | N36: 14" | O36: 355 | P36: H4 | R36: RA | S36: N | AD36: 3758 | AE36: =AD36/1000 -> 3.758 | AN36: =+AP36-AL36 -> 0 | AP36: =+CONCATENATE(AF36*$AF$4+AG36*$AG$4+AH36*$AH$4+AI36*$AI$4) -> 0 | AQ36: =AP36 -> 0 | AS36: =AH36 -> 0 | AT36: =AI36 -> 0
B37: 35 | C37: CC-403 | E37: Lixiviacion piscina emergencia | F37: =LEFT(K37,4) -> 3632 | I37: 4600027788-03632-502CA-00006 | J37: 0 | K37: 3632-RA-355-H4-0933-N | L37: 933 | M37: 4 | N37: 14" | O37: 355 | P37: H4 | R37: RA | S37: N | AD37: 6500 | AE37: =AD37/1000 -> 6.5 | AN37: =+AP37-AL37 -> 0 | AP37: =+CONCATENATE(AF37*$AF$4+AG37*$AG$4+AH37*$AH$4+AI37*$AI$4) -> 0 | AQ37: =AP37 -> 0 | AS37: =AH37 -> 0 | AT37: =AI37 -> 0
B38: 36 | C38: CC-403 | E38: Lixiviacion piscina emergencia | F38: =LEFT(K38,4) -> 3632 | I38: 4600027788-03632-502CA-00007 | J38: 0 | K38: 3632-RA-355-H4-0933-N | L38: 933 | M38: 5 | N38: 14" | O38: 355 | P38: H4 | R38: RA | S38: N | AD38: 1795 | AE38: =AD38/1000 -> 1.795 | AN38: =+AP38-AL38 -> 0 | AP38: =+CONCATENATE(AF38*$AF$4+AG38*$AG$4+AH38*$AH$4+AI38*$AI$4) -> 0 | AQ38: =AP38 -> 0 | AS38: =AH38 -> 0 | AT38: =AI38 -> 0
B39: 37 | C39: CC-403 | E39: Lixiviacion piscina emergencia | F39: =LEFT(K39,4) -> 3632 | I39: 4600027788-03632-502CA-00008 | J39: 0 | K39: 3632-RA-355-H4-0935-N | L39: 935 | M39: 1 | N39: 14" | O39: 355 | P39: H4 | R39: RA | S39: N | AD39: 8058 | AE39: =AD39/1000 -> 8.058 | AN39: =+AP39-AL39 -> 0 | AP39: =+CONCATENATE(AF39*$AF$4+AG39*$AG$4+AH39*$AH$4+AI39*$AI$4) -> 0 | AQ39: =AP39 -> 0 | AS39: =AH39 -> 0 | AT39: =AI39 -> 0
B40: 38 | C40: CC-403 | E40: Lixiviacion piscina emergencia | F40: =LEFT(K40,4) -> 3632 | I40: 4600027788-03632-300CA-00003 | K40: 3632-RA-800-H4-0938-N | L40: 938 | N40: 32" | O40: 800 | P40: H4 | R40: RA | S40: N | AD40: 15375 | AE40: =AD40/1000 -> 15.375 | AN40: =+AP40-AL40 -> 0 | AP40: =+CONCATENATE(AF40*$AF$4+AG40*$AG$4+AH40*$AH$4+AI40*$AI$4) -> 0 | AQ40: =AP40 -> 0 | AS40: =AH40 -> 0 | AT40: =AI40 -> 0
...

Sheet Soportes General
C2: LISTADO DE SOPORTES | O2: Pulgadas | P2: Suma de Cant.
O3: 0.75 | P3: 2
O4: 1 | P4: 506
B5: CENTINA | O5: 1.25 | P5: 3
B6: ITEM | C6: Clase | D6: Tag Soporte | E6: Dn Ø " | F6: Cant. | G6: Unidad | H6: Peso Unitario/kg | I6: Peso Total kg | J6: Estandar Soportes | K6: Rev | L6: Comentario | M6: Estatus Solicitud | O6: 1.5 | P6: 204
B7: 1 | C7: SA01 | D7: 3631-SA01-30" | E7: 30 | F7: 1 | G7: c/u | H7: 870 | I7: =H7*F7 -> 870 | J7: 4600027788-03630-000CA-00003 | K7: 3 | L7: El Gap Largo/Ancho y espesor dependera de material de cañeria | O7: 2 | P7: 292
B8: 2 | C8: SA07 | D8: 3631-SA07-12" | E8: 12 | F8: 4 | G8: c/u | H8: 189 | I8: =H8*F8 -> 756 | J8: 4600027788-03630-000CA-00004 | K8: 3 | L8: El Gap Largo/Ancho y espesor dependera de material de cañeria | O8: 3 | P8: 828
B9: 3 | C9: SA08 | D9: 3631-SA08-28" | E9: 28 | F9: 1 | G9: c/u | H9: 661 | I9: =H9*F9 -> 661 | J9: 4600027788-03630-000CA-00004 | K9: 3 | L9: El Gap Largo/Ancho y espesor dependera de material de cañeria | O9: 4 | P9: 75
B10: 4 | C10: SA09 | D10: 3631-SA09-24" | E10: 24 | F10: 1 | G10: c/u | H10: 417 | I10: =H10*F10 -> 417 | J10: 4600027788-03630-000CA-00005 | K10: 2 | L10: El Gap Largo/Ancho y espesor dependera de material de cañeria | O10: 6 | P10: 29
B11: 5 | C11: SA40 | D11: 3631-SA40-36" | E11: 26 | F11: 1 | G11: c/u | H11: 413 | I11: =H11*F11 -> 413 | J11: 4600027788-03630-000CA-00005 | K11: 2 | L11: El Gap Largo/Ancho y espesor dependera de material de cañeria | O11: 8 | P11: 39
B12: 6 | C12: SS02 | D12: 3631-SS02-16" | E12: 16 | F12: 9 | G12: c/u | H12: 48 | I12: =H12*F12 -> 432 | J12: 4600027788-03630-000CA-00003 | K12: 3 | L12: El Gap Largo/Ancho y espesor dependera de material de cañeria | O12: 10 | P12: 31
B13: 7 | C13: SS02 | D13: 3631-SS02-24" | E13: 24 | F13: 3 | G13: c/u | H13: 137 | I13: =H13*F13 -> 411 | J13: 4600027788-03630-000CA-00003 | K13: 3 | L13: El Gap Largo/Ancho y espesor dependera de material de cañeria | O13: 12 | P13: 306
B14: 8 | C14: SS02 | D14: 3631-SS02-30" | E14: 30 | F14: 4 | G14: c/u | H14: 227 | I14: =H14*F14 -> 908 | J14: 4600027788-03630-000CA-00003 | K14: 3 | L14: El Gap Largo/Ancho y espesor dependera de material de cañeria | O14: 14 | P14: 75
B15: 9 | C15: SS02 | D15: 3631-SS02-36" | E15: 36 | F15: 1 | G15: c/u | H15: 170 | I15: =H15*F15 -> 170 | J15: 4600027788-03630-000CA-00003 | K15: 3 | L15: El Gap Largo/Ancho y espesor dependera de material de cañeria | O15: Total general | P15: 2390
B16: 10 | C16: SS04 | D16: 3631-SS04-16" | E16: 16 | F16: 3 | G16: c/u | H16: 112 | I16: =H16*F16 -> 336 | J16: 4600027788-03630-000CA-00003 | K16: 3 | L16: El Gap Largo/Ancho y espesor dependera de material de cañeria
B17: 11 | C17: SS04 | D17: 3631-SS04-24" | E17: 24 | F17: 2 | G17: c/u | H17: 225 | I17: =H17*F17 -> 450 | J17: 4600027788-03630-000CA-00003 | K17: 3 | L17: El Gap Largo/Ancho y espesor dependera de material de cañeria
B18: 12 | C18: SS04 | D18: 3631-SS04-28" | E18: 28 | F18: 9 | G18: c/u | H18: 238 | I18: =H18*F18 -> 2142 | J18: 4600027788-03630-000CA-00003 | K18: 3 | L18: El Gap Largo/Ancho y espesor dependera de material de cañeria
B19: 13 | C19: SS04 | D19: 3631-SS04-36" | E19: 36 | F19: 15 | G19: c/u | H19: 451 | I19: =H19*F19 -> 6765 | J19: 4600027788-03630-000CA-00003 | K19: 3 | L19: El Gap Largo/Ancho y espesor dependera de material de cañeria
E21: Total | F21: =+SUM(F7:F20) -> 54 | G21: - | H21: - | I21: =SUM(I7:I20) -> 14731
B23: RED CONTRA INCENDIO
B24: ITEM | C24: Clase | D24: Tag Soporte | E24: Dn Ø" | F24: Cant. | G24: Unidad | H24: Peso Unitario/kg | I24: Peso Total kg | J24: Tag Linea | K24: Materialidad | L24: Planos de Soporte | M24: Estatus Solicitud
B25: 1 | C25: PU01 | D25: 6340-PU01-015 | E25: 1.5 | F25: 2 | G25: c/u | H25: 0.1 | I25: =F25*H25 -> 0.2 | J25: 6340-FP-1 1/2"-C3-0968-N | K25: Acero Carbono ASTM A36 o superior | L25: 4600027788-03630-000CA-00001 / 00002 / 00006
B26: 2 | C26: PU01 | D26: 6340-PU01-015 | E26: 1.5 | F26: 3 | G26: c/u | H26: 0.1 | I26: =F26*H26 -> 0.3 | J26: 6340-FP-1 1/2"-C3-0972-HC | K26: Acero Carbono ASTM A36 o superior | L26: 4600027788-03630-000CA-00001 / 00002 / 00006
B27: 3 | C27: SP22 | D27: 6340-SP22-001 | E27: 1.5 | F27: 3 | G27: c/u | H27: 2 | I27: =F27*H27 -> 6 | J27: 6340-FP-1 1/2"-C3-0972-HC | K27: Acero Carbono ASTM A36 o superior | L27: 4600027788-03630-000CA-00001 / 00002 / 00006
B28: 4 | C28: PU01 | D28: 6340-PU01-015 | E28: 1.5 | F28: 2 | G28: c/u | H28: 0.1 | I28: =F28*H28 -> 0.2 | J28: 6340-FP-1 1/2"-C3-0974-N | K28: Acero Carbono ASTM A36 o superior | L28: 4600027788-03630-000CA-00001 / 00002 / 00006
B29: 5 | C29: PU01 | D29: 6340-PU01-015 | E29: 1.5 | F29: 2 | G29: c/u | H29: 0.1 | I29: =F29*H29 -> 0.2 | J29: 6340-FP-1 1/2"-C3-0981-HC | K29: Acero Carbono ASTM A36 o superior | L29: 4600027788-03630-000CA-00001 / 00002 / 00006
B30: 6 | C30: SP22 | D30: 6340-SP22-001 | E30: 1.5 | F30: 2 | G30: c/u | H30: 2 | I30: =F30*H30 -> 4 | J30: 6340-FP-1 1/2"-C3-0981-HC | K30: Acero Carbono ASTM A36 o superior | L30: 4600027788-03630-000CA-00001 / 00002 / 00006
B31: 7 | C31: PU01 | D31: 6340-PU01-015 | E31: 1.5 | F31: 3 | G31: c/u | H31: 0.1 | I31: =F31*H31 -> 0.3 | J31: 6340-FP-1 1/2"-C3-0990-HC | K31: Acero Carbono ASTM A36 o superior | L31: 4600027788-03630-000CA-00001 / 00002 / 00006
B32: 8 | C32: SP22 | D32: 6340-SP22-001 | E32: 1.5 | F32: 3 | G32: c/u | H32: 2 | I32: =F32*H32 -> 6 | J32: 6340-FP-1 1/2"-C3-0990-HC | K32: Acero Carbono ASTM A36 o superior | L32: 4600027788-03630-000CA-00001 / 00002 / 00006
B33: 9 | C33: PU01 | D33: 6340-PU01-015 | E33: 1.5 | F33: 3 | G33: c/u | H33: 0.1 | I33: =F33*H33 -> 0.3 | J33: 6340-FP-1 1/2"-C3-0997-HC | K33: Acero Carbono ASTM A36 o superior | L33: 4600027788-03630-000CA-00001 / 00002 / 00006
B34: 10 | C34: SP22 | D34: 6340-SP22-001 | E34: 1.5 | F34: 3 | G34: c/u | H34: 2 | I34: =F34*H34 -> 6 | J34: 6340-FP-1 1/2"-C3-0997-HC | K34: Acero Carbono ASTM A36 o superior | L34: 4600027788-03630-000CA-00001 / 00002 / 00006
B35: 11 | C35: PU01 | D35: 6340-PU01-030 | E35: 3 | F35: 1 | G35: c/u | H35: 0.4 | I35: =F35*H35 -> 0.4 | J35: 6340-FP-1 1/2"-C3-0997-HC | K35: Acero Carbono ASTM A36 o superior | L35: 4600027788-03630-000CA-00001 / 00002 / 00006
B36: 12 | C36: SP39 | D36: 6340-SP39-001 | E36: 3 | F36: 1 | G36: c/u | H36: 5.6 | I36: =F36*H36 -> 5.6 | J36: 6340-FP-1 1/2"-C3-0997-HC | K36: Acero Carbono ASTM A36 o superior | L36: 4600027788-03630-000CA-00001 / 00002 / 00006
... B167: 143 | C167: SG01 | D167: 6340-SG01-120 | E167: 12 | F167: 9 | G167: c/u | H167: 6.3 | I167: =F167*H167 -> 56.7 | J167: 6340-FP-12"-C3-0966-HC | K167: Acero Carbono ASTM A36 o superior | L167: 4600027788-03630-000CA-00001 / 00002 / 00006
B168: 144 | C168: SL01 | D168: 6340-SL01-120 | E168: 12 | F168: 2 | G168: c/u | H168: 15.7 | I168: =F168*H168 -> 31.4 | J168: 6340-FP-12"-C3-0966-HC | K168: Acero Carbono ASTM A36 o superior | L168: 4600027788-03630-000CA-00001 / 00002 / 00006 | W168: 3" | X168: 12" | Y168: 14" | Z168: totales
B169: 145 | C169: SP01 | D169: 6340-SP01-402 | E169: 12 | F169: 9 | G169: c/u | H169: 17 | I169: =F169*H169 -> 153 | J169: 6340-FP-12"-C3-0966-HC | K169: Acero Carbono ASTM A36 o superior | L169: 4600027788-03630-000CA-00001 / 00002 / 00006 | V169: SP 42 | W169: - | X169: 64 | Y169: 20 | Z169: =+X169+Y169 -> 84
B170: 146 | C170: SS12 | D170: 6340-SS12-120 | E170: 12 | F170: 5 | G170: c/u | H170: 20 | I170: =F170*H170 -> 100 | J170: 6340-FP-12"-C3-0966-HC | K170: Acero Carbono ASTM A36 o superior | L170: 4600027788-03630-000CA-00001 / 00002 / 00006 | V170: SP 43 | W170: 132 | X170: - | Y170: - | Z170: 132
B171: 147 | C171: SZ02 | D171: 6340-SZ02-120 | E171: 12 | F171: 9 | G171: c/u | H171: 8.4 | I171: =F171*H171 -> 75.6 | J171: 6340-FP-12"-C3-0966-HC | K171: Acero Carbono ASTM A36 o superior | L171: 4600027788-03630-000CA-00001 / 00002 / 00006
B172: 148 | C172: SP26 | D172: 3640-SP26-502 | E172: 12 | F172: 2 | G172: c/u | H172: 205 | I172: =F172*H172 -> 410 | J172: 6340-FP-12"-C3-0978-HC | K172: Acero Carbono ASTM A36 o superior | L172: 4600027788-03630-000CA-00001 / 00002 / 00006
B173: 149 | C173: SP33 | D173: 3640-SP33-002 | E173: 12 | F173: 2 | G173: c/u | H173: 41 | I173: =F173*H173 -> 82 | J173: 6340-FP-12"-C3-0978-HC | K173: Acero Carbono ASTM A36 o superior | L173: 4600027788-03630-000CA-00001 / 00002 / 00006
...

Sheet Valvulas_General
B2: Listado Valvulas Manuales
B4: N° | C4: Ø | D4: Codigo | E4: Correlativo | F4: Tag | G4: Tipo de Valvula | H4: Descripcion | I4: Servicio | J4: Clase ASME/ Rating | K4: Presión de Diseño (kPa) | L4: Accionamiento | M4: N° de Línea | N4: N° P&ID Codelco | O4: Rev | P4: Comentario | S4: Resumen Sentina
B5: 1 | C5: 4" | D5: VBB | E5: 901 | F5: 4"-VBB-901 | G5: Válvula de Bola | H5: VÁLVULA DE BOLA CLASE 300 SEGÚN B16.34, FLANGES SEGÚN B16.5, OPERACIÓN MANUAL, CUERPO TITANIO ASTM B367 GR2, BOLA TITANIO ASTM B367 GR2, TRIM TITANIO ASTM B367 GR2, ASIENTO VITON C. | I5: Refino | J5: CL 300 | K5: 5.102 | L5: Manual con Palanca | M5: 3631-RA-16"-T1-0951-N | N5: 4600027788-03631-201CA-00002 | O5: 0 | R5: Cuenta de Codigo | S5: Etiquetas de columna
B6: 2 | C6: 4" | D6: VVT | E6: 901 | F6: 4"-VVT-901 | G6: Válvula de Venteo | H6: VÁLVULA DE VENTEO DE DOBLE / TRIPLE EFECTO, CLASE 300 SEGÚN AWWA C512, FLANGES SEGÚN B16.5, FLG, CUERPO PVDF, FLOTADOR EN ESPUMA DE POLIETILENO, TRIM TITANIO ASTM B367 GR2, ASIENTO VITON C. | I6: Refino | J6: CL 300 | K6: 5.102 | L6: N/A | M6: 3631-RA-16"-T1-0951-N | N6: 4600027788-03631-201CA-00002 | O6: 0 | R6: Etiquetas de fila | S6: 12" | T6: 16" | U6: 2" | V6: 24" | W6: 36" | X6: 4" | Y6: 6" | Z6: 8" | AA6: Total general
B7: 3 | C7: 2" | D7: VBB | E7: 903B | F7: 2"-VBB-903B | G7: Válvula de Bola | H7: VÁLVULA DE BOLA CLASE 300 SEGÚN B16.34, FLANGES SEGÚN B16.5, OPERACIÓN MANUAL, CUERPO TITANIO ASTM B367 GR2, BOLA TITANIO ASTM B367 GR2, TRIM TITANIO ASTM B367 GR2, ASIENTO VITON C. | I7: Refino | J7: CL 300 | K7: 5.102 | L7: Manual con Palanca | M7: 3631-RA-16"-T1-0951-N | N7: 4600027788-03631-201CA-00002 | O7: 0 | R7: Válvula de Bola | U7: 24 | X7: 5 | Y7: 4 | Z7: 3 | AA7: 36
B8: 4 | C8: 2" | D8: VBB | E8: 904B | F8: 2"-VBB-904B | G8: Válvula de Bola | H8: VÁLVULA DE BOLA CLASE 300 SEGÚN B16.34, FLANGES SEGÚN B16.5, OPERACIÓN MANUAL, CUERPO TITANIO ASTM B367 GR2, BOLA TITANIO ASTM B367 GR2, TRIM TITANIO ASTM B367 GR2, ASIENTO VITON C. | I8: Refino | J8: CL 300 | K8: 5.102 | L8: Manual con Palanca | M8: 3631-RA-16"-T1-0951-N | N8: 4600027788-03631-201CA-00002 | O8: 0 | R8: Valvula de Retención | T8: 4 | AA8: 4
B9: 5 | C9: 2" | D9: VBB | E9: 903 | F9: 2"-VBB-903 | G9: Válvula de Bola | H9: VÁLVULA DE BOLA CLASE 300 SEGÚN B16.34, FLANGES SEGÚN B16.5, OPERACIÓN MANUAL, CUERPO TITANIO ASTM B367 GR2, BOLA TITANIO ASTM B367 GR2, TRIM TITANIO ASTM B367 GR2, ASIENTO VITON C. | I9: Refino | J9: CL 300 | K9: 5.102 | L9: Manual con Palanca | M9: 3631-RA-16"-T1-0951-N | N9: 4600027788-03631-201CA-00002 | O9: 0 | R9: Válvula de Venteo | X9: 5 | Y9: 4 | Z9: 3 | AA9: 12
B10: 6 | C10: 2" | D10: VBB | E10: 904 | F10: 2"-VBB-904 | G10: Válvula de Bola | H10: VÁLVULA DE BOLA CLASE 300 SEGÚN B16.34, FLANGES SEGÚN B16.5, OPERACIÓN MANUAL, CUERPO TITANIO ASTM B367 GR2, BOLA TITANIO ASTM B367 GR2, TRIM TITANIO ASTM B367 GR2, ASIENTO VITON C. | I10: Refino | J10: CL 300 | K10: 5.102 | L10: Manual con Palanca | M10: 3631-RA-16"-T1-0951-N | N10: 4600027788-03631-201CA-00002 | O10: 0 | R10: Válvula Mariposa | S10: 9 | T10: 5 | V10: 1 | W10: 1 | AA10: 16
B11: 7 | C11: 16" | D11: VRC | E11: 901 | F11: 16"-VRC-901 | G11: Valvula de Retención | H11: VÁLVULA DE RETENCIÓN TIPO DUO CHECK ASME B16.34, CL 300 WAFER, PARA FLANGES ASME B16.5, CUERPO Y TRIM TITANIO ASTM B367 GR C2. | I11: Refino | J11: CL 300 | K11: 5.102 | L11: N/A | M11: 3631-RA-16"-T1-0951-N | N11: 4600027788-03631-201CA-00002 | O11: 0 | R11: Total general | S11: 9 | T11: 9 | U11: 24 | V11: 1 | W11: 1 | X11: 10 | Y11: 8 | Z11: 6 | AA11: 68
B12: 8 | C12: 2" | D12: VBB | E12: 925 | F12: 2"-VBB-925 | G12: Válvula de Bola | H12: VÁLVULA DE BOLA CLASE 300 SEGÚN B16.34, FLANGES SEGÚN B16.5, OPERACIÓN MANUAL, CUERPO TITANIO ASTM B367 GR2, BOLA TITANIO ASTM B367 GR2, TRIM TITANIO ASTM B367 GR2, ASIENTO VITON C. | I12: Refino | J12: CL 300 | K12: 5.102 | L12: Manual con Palanca | M12: 3631-RA-16"-T1-0951-N | N12: 4600027788-03631-201CA-00002 | O12: 0
B13: 9 | C13: 16" | D13: VMP | E13: 901 | F13: 16"-VMP-901 | G13: Válvula Mariposa | H13: VÁLVULA DE MARIPOSA HIGH PERFOMANCE CLASE 300 SEGÚN B16.34, FLANGES SEGÚN B16.5, LUG, OPERADA POR ENGRANAJE, CUERPO TITANIO ASTM B367 GR C2, DISCO TITANIO ASTM B367 GR2, ASIENTO VITON C. | I13: Refino | J13: CL 300 | K13: 5.102 | L13: Manual con Reductor | M13: 3631-RA-16"-T1-0951-N | N13: 4600027788-03631-201CA-00002 | O13: 0
B14: 10 | C14: 4" | D14: VBB | E14: 902 | F14: 4"-VBB-902 | G14: Válvula de Bola | H14: VÁLVULA DE BOLA CLASE 300 SEGÚN B16.34, FLANGES SEGÚN B16.5, OPERACIÓN MANUAL, CUERPO TITANIO ASTM B367 GR2, BOLA TITANIO ASTM B367 GR2, TRIM TITANIO ASTM B367 GR2, ASIENTO VITON C. | I14: Refino | J14: CL 300 | K14: 5.102 | L14: Manual con Palanca | M14: 3631-RA-16"-T1-0952-N | N14: 4600027788-03631-201CA-00002 | O14: 0
B15: 11 | C15: 4" | D15: VVT | E15: 902 | F15: 4"-VVT-902 | G15: Válvula de Venteo | H15: VÁLVULA DE VENTEO DE DOBLE / TRIPLE EFECTO, CLASE 300 SEGÚN AWWA C512, FLANGES SEGÚN B16.5, FLG, CUERPO PVDF, FLOTADOR EN ESPUMA DE POLIETILENO, TRIM TITANIO ASTM B367 GR2, ASIENTO VITON C. | I15: Refino | J15: CL 300 | K15: 5.102 | L15: N/A | M15: 3631-RA-16"-T1-0952-N | N15: 4600027788-03631-201CA-00002 | O15: 0
B16: 12 | C16: 2" | D16: VBB | E16: 907B | F16: 2"-VBB-907B | G16: Válvula de Bola | H16: VÁLVULA DE BOLA CLASE 300 SEGÚN B16.34, FLANGES SEGÚN B16.5, OPERACIÓN MANUAL, CUERPO TITANIO ASTM B367 GR2, BOLA TITANIO ASTM B367 GR2, TRIM TITANIO ASTM B367 GR2, ASIENTO VITON C. | I16: Refino | J16: CL 300 | K16: 5.102 | L16: Manual con Palanca | M16: 3631-RA-16"-T1-0952-N | N16: 4600027788-03631-201CA-00002 | O16: 0
B17: 13 | C17: 2" | D17: VBB | E17: 908B | F17: 2"-VBB-908B | G17: Válvula de Bola | H17: VÁLVULA DE BOLA CLASE 300 SEGÚN B16.34, FLANGES SEGÚN B16.5, OPERACIÓN MANUAL, CUERPO TITANIO ASTM B367 GR2, BOLA TITANIO ASTM B367 GR2, TRIM TITANIO ASTM B367 GR2, ASIENTO VITON C. | I17: Refino | J17: CL 300 | K17: 5.102 | L17: Manual con Palanca | M17: 3631-RA-16"-T1-0952-N | N17: 4600027788-03631-201CA-00002 | O17: 0
B18: 14 | C18: 2" | D18: VBB | E18: 907 | F18: 2"-VBB-907 | G18: Válvula de Bola | H18: VÁLVULA DE BOLA CLASE 300 SEGÚN B16.34, FLANGES SEGÚN B16.5, OPERACIÓN MANUAL, CUERPO TITANIO ASTM B367 GR2, BOLA TITANIO ASTM B367 GR2, TRIM TITANIO ASTM B367 GR2, ASIENTO VITON C. | I18: Refino | J18: CL 300 | K18: 5.102 | L18: Manual con Palanca | M18: 3631-RA-16"-T1-0952-N | N18: 4600027788-03631-201CA-00002 | O18: 0
B19: 15 | C19: 2" | D19: VBB | E19: 908 | F19: 2"-VBB-908 | G19: Válvula de Bola | H19: VÁLVULA DE BOLA CLASE 300 SEGÚN B16.34, FLANGES SEGÚN B16.5, OPERACIÓN MANUAL, CUERPO TITANIO ASTM B367 GR2, BOLA TITANIO ASTM B367 GR2, TRIM TITANIO ASTM B367 GR2, ASIENTO VITON C. | I19: Refino | J19: CL 300 | K19: 5.102 | L19: Manual con Palanca | M19: 3631-RA-16"-T1-0952-N | N19: 4600027788-03631-201CA-00002 | O19: 0
B20: 16 | C20: 16" | D20: VRC | E20: 902 | F20: 16"-VRC-902 | G20: Valvula de Retención | H20: VÁLVULA DE RETENCIÓN TIPO DUO CHECK ASME B16.34, CL 300 WAFER, PARA FLANGES ASME B16.5, CUERPO Y TRIM TITANIO ASTM B367 GR C2. | I20: Refino | J20: CL 300 | K20: 5.102 | L20: N/A | M20: 3631-RA-16"-T1-0952-N | N20: 4600027788-03631-201CA-00002 | O20: 0
B21: 17 | C21: 2" | D21: VBB | E21: 926 | F21: 2"-VBB-926 | G21: Válvula de Bola | H21: VÁLVULA DE BOLA CLASE 300 SEGÚN B16.34, FLANGES SEGÚN B16.5, OPERACIÓN MANUAL, CUERPO TITANIO ASTM B367 GR2, BOLA TITANIO ASTM B367 GR2, TRIM TITANIO ASTM B367 GR2, ASIENTO VITON C. | I21: Refino | J21: CL 300 | K21: 5.102 | L21: Manual con Palanca | M21: 3631-RA-16"-T1-0952-N | N21: 4600027788-03631-201CA-00002 | O21: 0
B22: 18 | C22: 16" | D22: VMP | E22: 902 | F22: 16"-VMP-902 | G22: Válvula Mariposa | H22: VÁLVULA DE MARIPOSA HIGH PERFOMANCE CLASE 300 SEGÚN B16.34, FLANGES SEGÚN B16.5, LUG, OPERADA POR ENGRANAJE, CUERPO TITANIO ASTM B367 GR C2, DISCO TITANIO ASTM B367 GR2, ASIENTO VITON C. | I22: Refino | J22: CL 300 | K22: 5.102 | L22: Manual con Reductor | M22: 3631-RA-16"-T1-0952-N | N22: 4600027788-03631-201CA-00002 | O22: 0
B23: 19 | C23: 4" | D23: VBB | E23: 903 | F23: 4"-VBB-903 | G23: Válvula de Bola | H23: VÁLVULA DE BOLA CLASE 300 SEGÚN B16.34, FLANGES SEGÚN B16.5, OPERACIÓN MANUAL, CUERPO TITANIO ASTM B367 GR2, BOLA TITANIO ASTM B367 GR2, TRIM TITANIO ASTM B367 GR2, ASIENTO VITON C. | I23: Refino | J23: CL 300 | K23: 5.102 | L23: Manual con Palanca | M23: 3631-RA-16"-T1-0953-N | N23: 4600027788-03631-201CA-00002 | O23: 0
B24: 20 | C24: 4" | D24: VVT | E24: 903 | F24: 4"-VVT-903 | G24: Válvula de Venteo | H24: VÁLVULA DE VENTEO DE DOBLE / TRIPLE EFECTO, CLASE 300 SEGÚN AWWA C512, FLANGES SEGÚN B16.5, FLG, CUERPO PVDF, FLOTADOR EN ESPUMA DE POLIETILENO, TRIM TITANIO ASTM B367 GR2, ASIENTO VITON C. | I24: Refino | J24: CL 300 | K24: 5.102 | L24: N/A | M24: 3631-RA-16"-T1-0953-N | N24: 4600027788-03631-201CA-00002 | O24: 0
B25: 21 | C25: 2" | D25: VBB | E25: 911B | F25: 2"-VBB-911B | G25: Válvula de Bola | H25: VÁLVULA DE BOLA CLASE 300 SEGÚN B16.34, FLANGES SEGÚN B16.5, OPERACIÓN MANUAL, CUERPO TITANIO ASTM B367 GR2, BOLA TITANIO ASTM B367 GR2, TRIM TITANIO ASTM B367 GR2, ASIENTO VITON C. | I25: Refino | J25: CL 300 | K25: 5.102 | L25: Manual con Palanca | M25: 3631-RA-16"-T1-0953-N | N25: 4600027788-03631-201CA-00002 | O25: 0
B26: 22 | C26: 2" | D26: VBB | E26: 912B | F26: 2"-VBB-912B | G26: Válvula de Bola | H26: VÁLVULA DE BOLA CLASE 300 SEGÚN B16.34, FLANGES SEGÚN B16.5, OPERACIÓN MANUAL, CUERPO TITANIO ASTM B367 GR2, BOLA TITANIO ASTM B367 GR2, TRIM TITANIO ASTM B367 GR2, ASIENTO VITON C. | I26: Refino | J26: CL 300 | K26: 5.102 | L26: Manual con Palanca | M26: 3631-RA-16"-T1-0953-N | N26: 4600027788-03631-201CA-00002 | O26: 0
B27: 23 | C27: 2" | D27: VBB | E27: 911 | F27: 2"-VBB-911 | G27: Válvula de Bola | H27: VÁLVULA DE BOLA CLASE 300 SEGÚN B16.34, FLANGES SEGÚN B16.5, OPERACIÓN MANUAL, CUERPO TITANIO ASTM B367 GR2, BOLA TITANIO ASTM B367 GR2, TRIM TITANIO ASTM B367 GR2, ASIENTO VITON C. | I27: Refino | J27: CL 300 | K27: 5.102 | L27: Manual con Palanca | M27: 3631-RA-16"-T1-0953-N | N27: 4600027788-03631-201CA-00002 | O27: 0
B28: 24 | C28: 2" | D28: VBB | E28: 912 | F28: 2"-VBB-912 | G28: Válvula de Bola | H28: VÁLVULA DE BOLA CLASE 300 SEGÚN B16.34, FLANGES SEGÚN B16.5, OPERACIÓN MANUAL, CUERPO TITANIO ASTM B367 GR2, BOLA TITANIO ASTM B367 GR2, TRIM TITANIO ASTM B367 GR2, ASIENTO VITON C. | I28: Refino | J28: CL 300 | K28: 5.102 | L28: Manual con Palanca | M28: 3631-RA-16"-T1-0953-N | N28: 4600027788-03631-201CA-00002 | O28: 0
B29: 25 | C29: 16" | D29: VRC | E29: 903 | F29: 16"-VRC-903 | G29: Valvula de Retención | H29: VÁLVULA DE RETENCIÓN TIPO DUO CHECK ASME B16.34, CL 300 WAFER, PARA FLANGES ASME B16.5, CUERPO Y TRIM TITANIO ASTM B367 GR C2. | I29: Refino | J29: CL 300 | K29: 5.102 | L29: N/A | M29: 3631-RA-16"-T1-0953-N | N29: 4600027788-03631-201CA-00002 | O29: 0
B30: 26 | C30: 2" | D30: VBB | E30: 927 | F30: 2"-VBB-927 | G30: Válvula de Bola | H30: VÁLVULA DE BOLA CLASE 300 SEGÚN B16.34, FLANGES SEGÚN B16.5, OPERACIÓN MANUAL, CUERPO TITANIO ASTM B367 GR2, BOLA TITANIO ASTM B367 GR2, TRIM TITANIO ASTM B367 GR2, ASIENTO VITON C. | I30: Refino | J30: CL 300 | K30: 5.102 | L30: Manual con Palanca | M30: 3631-RA-16"-T1-0953-N | N30: 4600027788-03631-201CA-00002 | O30: 0
B31: 27 | C31: 16" | D31: VMP | E31: 903 | F31: 16"-VMP-903 | G31: Válvula Mariposa | H31: VÁLVULA DE MARIPOSA HIGH PERFOMANCE CLASE 300 SEGÚN B16.34, FLANGES SEGÚN B16.5, LUG, OPERADA POR ENGRANAJE, CUERPO TITANIO ASTM B367 GR C2, DISCO TITANIO ASTM B367 GR2, ASIENTO VITON C. | I31: Refino | J31: CL 300 | K31: 5.102 | L31: Manual con Reductor | M31: 3631-RA-16"-T1-0953-N | N31: 4600027788-03631-201CA-00002 | O31: 0
B32: 28 | C32: 4" | D32: VBB | E32: 904 | F32: 4"-VBB-904 | G32: Válvula de Bola | H32: VÁLVULA DE BOLA CLASE 300 SEGÚN B16.34, FLANGES SEGÚN B16.5, OPERACIÓN MANUAL, CUERPO TITANIO ASTM B367 GR2, BOLA TITANIO ASTM B367 GR2, TRIM TITANIO ASTM B367 GR2, ASIENTO VITON C. | I32: Refino | J32: CL 300 | K32: 5.102 | L32: Manual con Palanca | M32: 3631-RA-16"-T1-0954-N | N32: 4600027788-03631-201CA-00002 | O32: 0
B33: 29 | C33: 4" | D33: VVT | E33: 904 | F33: 4"-VVT-904 | G33: Válvula de Venteo | H33: VÁLVULA DE VENTEO DE DOBLE / TRIPLE EFECTO, CLASE 300 SEGÚN AWWA C512, FLANGES SEGÚN B16.5, FLG, CUERPO PVDF, FLOTADOR EN ESPUMA DE POLIETILENO, TRIM TITANIO ASTM B367 GR2, ASIENTO VITON C. | I33: Refino | J33: CL 300 | K33: 5.102 | L33: N/A | M33: 3631-RA-16"-T1-0954-N | N33: 4600027788-03631-201CA-00002 | O33: 0
B34: 30 | C34: 2" | D34: VBB | E34: 915B | F34: 2"-VBB-915B | G34: Válvula de Bola | H34: VÁLVULA DE BOLA CLASE 300 SEGÚN B16.34, FLANGES SEGÚN B16.5, OPERACIÓN MANUAL, CUERPO TITANIO ASTM B367 GR2, BOLA TITANIO ASTM B367 GR2, TRIM TITANIO ASTM B367 GR2, ASIENTO VITON C. | I34: Refino | J34: CL 300 | K34: 5.102 | L34: Manual con Palanca | M34: 3631-RA-16"-T1-0954-N | N34: 4600027788-03631-201CA-00002 | O34: 0
B35: 31 | C35: 2" | D35: VBB | E35: 916B | F35: 2"-VBB-916B | G35: Válvula de Bola | H35: VÁLVULA DE BOLA CLASE 300 SEGÚN B16.34, FLANGES SEGÚN B16.5, OPERACIÓN MANUAL, CUERPO TITANIO ASTM B367 GR2, BOLA TITANIO ASTM B367 GR2, TRIM TITANIO ASTM B367 GR2, ASIENTO VITON C. | I35: Refino | J35: CL 300 | K35: 5.102 | L35: Manual con Palanca | M35: 3631-RA-16"-T1-0954-N | N35: 4600027788-03631-201CA-00002 | O35: 0
B36: 32 | C36: 2" | D36: VBB | E36: 915 | F36: 2"-VBB-915 | G36: Válvula de Bola | H36: VÁLVULA DE BOLA CLASE 300 SEGÚN B16.34, FLANGES SEGÚN B16.5, OPERACIÓN MANUAL, CUERPO TITANIO ASTM B367 GR2, BOLA TITANIO ASTM B367 GR2, TRIM TITANIO ASTM B367 GR2, ASIENTO VITON C. | I36: Refino | J36: CL 300 | K36: 5.102 | L36: Manual con Palanca | M36: 3631-RA-16"-T1-0954-N | N36: 4600027788-03631-201CA-00002 | O36: 0
B37: 33 | C37: 2" | D37: VBB | E37: 916 | F37: 2"-VBB-916 | G37: Válvula de Bola | H37: VÁLVULA DE BOLA CLASE 300 SEGÚN B16.34, FLANGES SEGÚN B16.5, OPERACIÓN MANUAL, CUERPO TITANIO ASTM B367 GR2, BOLA TITANIO ASTM B367 GR2, TRIM TITANIO ASTM B367 GR2, ASIENTO VITON C. | I37: Refino | J37: CL 300 | K37: 5.102 | L37: Manual con Palanca | M37: 3631-RA-16"-T1-0954-N | N37: 4600027788-03631-201CA-00002 | O37: 0
B38: 34 | C38: 16" | D38: VRC | E38: 904 | F38: 16"-VRC-904 | G38: Valvula de Retención | H38: VÁLVULA DE RETENCIÓN TIPO DUO CHECK ASME B16.34, CL 300 WAFER, PARA FLANGES ASME B16.5, CUERPO Y TRIM TITANIO ASTM B367 GR C2. | I38: Refino | J38: CL 300 | K38: 5.102 | L38: N/A | M38: 3631-RA-16"-T1-0954-N | N38: 4600027788-03631-201CA-00002 | O38: 0
B39: 35 | C39: 2" | D39: VBB | E39: 928 | F39: 2"-VBB-928 | G39: Válvula de Bola | H39: VÁLVULA DE BOLA CLASE 300 SEGÚN B16.34, FLANGES SEGÚN B16.5, OPERACIÓN MANUAL, CUERPO TITANIO ASTM B367 GR2, BOLA TITANIO ASTM B367 GR2, TRIM TITANIO ASTM B367 GR2, ASIENTO VITON C. | I39: Refino | J39: CL 300 | K39: 5.102 | L39: Manual con Palanca | M39: 3631-RA-16"-T1-0954-N | N39: 4600027788-03631-201CA-00002 | O39: 0
B40: 36 | C40: 16" | D40: VMP | E40: 904 | F40: 16"-VMP-904 | G40: Válvula Mariposa | H40: VÁLVULA DE MARIPOSA HIGH PERFOMANCE CLASE 300 SEGÚN B16.34, FLANGES SEGÚN B16.5, LUG, OPERADA POR ENGRANAJE, CUERPO TITANIO ASTM B367 GR C2, DISCO TITANIO ASTM B367 GR2, ASIENTO VITON C. | I40: Refino | J40: CL 300 | K40: 5.102 | L40: Manual con Reductor | M40: 3631-RA-16"-T1-0954-N | N40: 4600027788-03631-201CA-00002 | O40: 0
B41: 37 | C41: 16" | D41: VMP | E41: 901 | F41: 16"-VMP-901 | G41: Válvula Mariposa | H41: VÁLVULA DE MARIPOSA HIGH PERFOMANCE CLASE 150 SEGÚN B16.34, FLANGES SEGÚN B16.5, LUG, OPERADA POR ENGRANAJE, CUERPO TITANIO ASTM B367 GR C2, DISCO TITANIO ASTM B367 GR2, ASIENTO VITON C. | I41: Refino | J41: CL 150 | K41: 1.999 | L41: Manual con Reductor | M41: 3631-RA-400-H1-0956-N | N41: 4600027788-03631-201CA-00002 | O41: 0
B42: 38 | C42: 2" | D42: VBB | E42: 929 | F42: 2"-VBB-929 | G42: Válvula de Bola | H42: VÁLVULA DE BOLA CLASE 300 SEGÚN B16.34, FLANGES SEGÚN B16.5, OPERACIÓN MANUAL, CUERPO TITANIO ASTM B367 GR2, BOLA TITANIO ASTM B367 GR2, TRIM TITANIO ASTM B367 GR2, ASIENTO VITON C. | I42: Refino | J42: CL 300 | K42: 5.102 | L42: Manual con Palanca | M42: 3631-RA-30"-T1-0955-N | N42: 4600027788-03631-201CA-00002 | O42: 0
...

Sheet Volumen_Obra
B2: 2.1 | C2: MANEJO RIPIOS
B3: 2.2 | C3: REGADIO LIXIVIACION SECUNDARIA
B4: 2.3 | C4: MANEJO DE SOLUCIONES PLS
B5: 2.4 | C5: CONDUCCION
B6: 2.5 | C6: SISTEMA CONTRA INCENDIO
B7: 2.6 | C7: RECEPCION Y SUMINISTRO ENERGIA ELECTRICA
H8: =SUBTOTAL(9,H10:H704) -> 19288.671
B9: Ítem | C9: AREA | D9: APORTES | E9: DESCRIPCION | F9: UNID | G9: CANT | H9: POM
B10: 2.1.1.1.1 | C10: MANEJO RIPIOS | D10: PPC | E10: Emplantillado G-10 | F10: m3 | G10: 17 | H10: =SUMIFS(Itemizado_Piping!$O$5:$O$93,Itemizado_Piping!$C$5:$C$93,Volumen_Obra!B10) -> 0
B11: 2.1.1.1.2 | C11: MANEJO RIPIOS | D11: PPC | E11: Hormigón Fundaciones, Muro y Radier G-25 | F11: m3 | G11: 140 | H11: =SUMIFS(Itemizado_Piping!$O$5:$O$93,Itemizado_Piping!$C$5:$C$93,Volumen_Obra!B11) -> 0
B12: 2.1.1.1.3 | C12: MANEJO RIPIOS | D12: PPC | E12: Acero de refuerzo A630-420H | F12: kg | G12: 8920 | H12: =SUMIFS(Itemizado_Piping!$O$5:$O$93,Itemizado_Piping!$C$5:$C$93,Volumen_Obra!B12) -> 0
B13: 2.1.1.1.4 | C13: MANEJO RIPIOS | D13: PPC | E13: Excavación estructural (incluye excavación malla a tierra) | F13: m3 | G13: 529 | H13: =SUMIFS(Itemizado_Piping!$O$5:$O$93,Itemizado_Piping!$C$5:$C$93,Volumen_Obra!B13) -> 0
B14: 2.1.1.1.5 | C14: MANEJO RIPIOS | D14: PPC | E14: Relleno estructural compactado (incluye relleno malla a tierra) | F14: m3 | G14: 417 | H14: =SUMIFS(Itemizado_Piping!$O$5:$O$93,Itemizado_Piping!$C$5:$C$93,Volumen_Obra!B14) -> 0
B15: 2.1.1.10.1 | C15: MANEJO RIPIOS | D15: PPC | E15: Suministro e Instalación Conductor desnudo blando, clase B, 19 hebras N° 2/0 AWG | F15: m | G15: 120 | H15: =SUMIFS(Itemizado_Piping!$O$5:$O$93,Itemizado_Piping!$C$5:$C$93,Volumen_Obra!B15) -> 0
B16: 2.1.1.10.2 | C16: MANEJO RIPIOS | D16: PPC | E16: Suministro e Instalación Conductor desnudo blando, clase B, 19 hebras N° 4/0 AWG | F16: m | G16: 560 | H16: =SUMIFS(Itemizado_Piping!$O$5:$O$93,Itemizado_Piping!$C$5:$C$93,Volumen_Obra!B16) -> 0
B17: 2.1.1.10.3 | C17: MANEJO RIPIOS | D17: PPC | E17: Suministro y Montaje de cámaras de registro | F17: uni | G17: 4 | H17: =SUMIFS(Itemizado_Piping!$O$5:$O$93,Itemizado_Piping!$C$5:$C$93,Volumen_Obra!B17) -> 0
B18: 2.1.1.10.4 | C18: MANEJO RIPIOS | D18: PPC | E18: Suministro y Montaje de GEL para mejoramiento de resistividad de suelo (Sacos de 14kilos) | F18: uni | G18: 280 | H18: =SUMIFS(Itemizado_Piping!$O$5:$O$93,Itemizado_Piping!$C$5:$C$93,Volumen_Obra!B18) -> 0
B19: 2.1.1.10.5 | C19: MANEJO RIPIOS | D19: PPC | E19: Suministro e Instalación Cables, canalizaciones y materiales menores | F19: gl | G19: 1 | H19: =SUMIFS(Itemizado_Piping!$O$5:$O$93,Itemizado_Piping!$C$5:$C$93,Volumen_Obra!B19) -> 0
B20: 2.1.1.10.6 | C20: MANEJO RIPIOS | D20: PPC | E20: Construcción Malla puesta a tierra: moldes soldadura termofusión, cámara de registro, etc. | F20: gl | G20: 1 | H20: =SUMIFS(Itemizado_Piping!$O$5:$O$93,Itemizado_Piping!$C$5:$C$93,Volumen_Obra!B20) -> 0
B21: 2.1.1.11.1 | C21: MANEJO RIPIOS | D21: PPD | E21: Montaje, conexionado de estación GPS repetidora 03622-ZT-1000 de acuerdo a puntos topográficos que se indicarán. incluye su infraestructura civil (para que termine en base de hormigón) de acuerdo a plano 4600020303-06700-221AT-00002. | F21: uni | G21: 1 | H21: =SUMIFS(Itemizado_Piping!$O$5:$O$93,Itemizado_Piping!$C$5:$C$93,Volumen_Obra!B21) -> 0
... B43: 2.1.1.2.6 | C43: MANEJO RIPIOS | D43: PPD | E43: Suministro y Montaje de Barandas de acceso para la Sala Eléctrica | F43: m | G43: 70 | H43: =SUMIFS(Itemizado_Piping!$O$5:$O$93,Itemizado_Piping!$C$5:$C$93,Volumen_Obra!B43) -> 0
B44: 2.1.1.3.1 | D44: PPD | E44: Montaje Sala Eléctrica prefabricada 27 x 6 x 3,5 m - 220-SEL-011 | F44: uni | G44: 1 | H44: =SUMIFS(Itemizado_Piping!$O$5:$O$93,Itemizado_Piping!$C$5:$C$93,Volumen_Obra!B44) -> 0
B45: 2.1.1.3.2 | D45: PPD | E45: Montaje Equipo Aire Acondicionado, Exterior | F45: uni | G45: 1 | H45: =SUMIFS(Itemizado_Piping!$O$5:$O$93,Itemizado_Piping!$C$5:$C$93,Volumen_Obra!B45) -> 0
B46: 2.1.1.3.3 | D46: PPD | E46: Montaje Ducto de Barras MT de 3000A | F46: uni | G46: 1 | H46: =SUMIFS(Itemizado_Piping!$O$5:$O$93,Itemizado_Piping!$C$5:$C$93,Volumen_Obra!B46) -> 0
B47: 2.1.1.3.4 | D47: PPD | E47: Montaje Sistema Sobrepresión, Exterior | F47: uni | G47: 1 | H47: =SUMIFS(Itemizado_Piping!$O$5:$O$93,Itemizado_Piping!$C$5:$C$93,Volumen_Obra!B47) -> 0
B48: 2.1.1.3.5 | D48: PPD | E48: Montaje Resistencia de Puesta a Tierra, Exterior | F48: uni | G48: 1 | H48: =SUMIFS(Itemizado_Piping!$O$5:$O$93,Itemizado_Piping!$C$5:$C$93,Volumen_Obra!B48) -> 0
B49: 2.1.1.3.6 | D49: PPD | E49: Montaje Transformador 10/13 MVA,KNAN KNAF 23/4,16 kV, Exterior | F49: uni | G49: 1 | H49: =SUMIFS(Itemizado_Piping!$O$5:$O$93,Itemizado_Piping!$C$5:$C$93,Volumen_Obra!B49) -> 0
B50: 2.1.1.3.7 | D50: PPD | E50: Montaje Transformador 300 KVA de 4,16/0,6 kV, Exterior | F50: uni | G50: 1 | H50: =SUMIFS(Itemizado_Piping!$O$5:$O$93,Itemizado_Piping!$C$5:$C$93,Volumen_Obra!B50) -> 0
B51: 2.1.1.3.8 | D51: PPD | E51: Montaje Transformador 150 KVA de 600/400-231 V, Exterior | F51: uni | G51: 1 | H51: =SUMIFS(Itemizado_Piping!$O$5:$O$93,Itemizado_Piping!$C$5:$C$93,Volumen_Obra!B51) -> 0
B52: 2.1.1.3.9 | D52: PPD | E52: Montaje Celda GIS a piso 23kV, y apoyo en puesta marcha | F52: uni | G52: 2 | H52: =SUMIFS(Itemizado_Piping!$O$5:$O$93,Itemizado_Piping!$C$5:$C$93,Volumen_Obra!B52) -> 0
B53: 2.1.1.4.1 | D53: PPC | E53: Construcción Cámara Eléctrica de hormigón 2000x2000x2400 mm con tapa | F53: un | G53: 8 | H53: =SUMIFS(Itemizado_Piping!$O$5:$O$93,Itemizado_Piping!$C$5:$C$93,Volumen_Obra!B53) -> 0
B54: 2.1.1.4.2 | D54: PPC | E54: Construcción Banco de Ductos reforzado para tránsito pesado de 1610x1100 mm | F54: m | G54: 93 | H54: =SUMIFS(Itemizado_Piping!$O$5:$O$93,Itemizado_Piping!$C$5:$C$93,Volumen_Obra!B54) -> 0
B55: 2.1.1.4.3 | D55: PPC | E55: Construcción Banco de Ductos reforzado para tránsito pesado de 600x600 mm | F55: m | G55: 252 | H55: =SUMIFS(Itemizado_Piping!$O$5:$O$93,Itemizado_Piping!$C$5:$C$93,Volumen_Obra!B55) -> 0
... B495: 2.6.1.2.5 | D495: PPC | E495: Construcción Cámara Eléctrica de hormigón 2000x2000x2400 mm | F495: un | G495: 4 | H495: =SUMIFS(Itemizado_Piping!$O$5:$O$93,Itemizado_Piping!$C$5:$C$93,Volumen_Obra!B495) -> 0
B496: 3.1.1 | E496: Bulldozer semi-U 9,4m3 (D8) | F496: HM | G496: 150 | H496: =SUMIFS(Itemizado_Piping!$O$5:$O$93,Itemizado_Piping!$C$5:$C$93,Volumen_Obra!B496) -> 0
B497: 3.1.10 | E497: Torre de iluminación | F497: HM | G497: 500 | H497: =SUMIFS(Itemizado_Piping!$O$5:$O$93,Itemizado_Piping!$C$5:$C$93,Volumen_Obra!B497) -> 0
B498: 3.1.11 | E498: Generador | F498: HM | G498: 800 | H498: =SUMIFS(Itemizado_Piping!$O$5:$O$93,Itemizado_Piping!$C$5:$C$93,Volumen_Obra!B498) -> 0
B499: 3.1.12 | E499: Camión Plano | F499: HM | G499: 500 | H499: =SUMIFS(Itemizado_Piping!$O$5:$O$93,Itemizado_Piping!$C$5:$C$93,Volumen_Obra!B499) -> 0
B500: 3.1.13 | E500: Grúa Horquilla | F500: HM | G500: 300 | H500: =SUMIFS(Itemizado_Piping!$O$5:$O$93,Itemizado_Piping!$C$5:$C$93,Volumen_Obra!B500) -> 0
B501: 3.1.14 | E501: Cuadrilla Distintas especialidades | F501: HH | G501: 5000 | H501: =SUMIFS(Itemizado_Piping!$O$5:$O$93,Itemizado_Piping!$C$5:$C$93,Volumen_Obra!B501) -> 0
...

Sheet POM Y AVANCE
C2: MONTO CONTRATO | O2: =O3+O9+O16 -> 12904186214 | P2: =P3+P9+P16 -> 1.9523797e+10 | Q2: =Q3+Q9+Q16 -> 2.6323838e+09 | R2: =R3+R9+R16 -> 4.6030447e+09 | S2: =S3+S9+S16 -> 1.4189319e+10 | T2: =T3+T9+T16 -> 5.3852731e+10 | W2: =W3+W9+W16 -> 12904186214 | X2: =X3+X9+X16 -> 1.9523797e+10 | Y2: =Y3+Y9+Y16 -> 2.6323838e+09 | Z2: =Z3+Z9+Z16 -> 4.6030447e+09 | AA2: =AA3+AA9+AA16 -> 1.298824e+10 | AB2: =AB3+AB9+AB16 -> 5.2651652e+10 | AE2: =AE3+AE9+AE16 -> 0 | AF2: =AF3+AF9+AF16 -> 0 | AG2: =AG3+AG9+AG16 -> 0 | AH2: =AH3+AH9+AH16 -> 0 | AI2: =AI3+AI9+AI16 -> 0 | AJ2: =AJ3+AJ9+AJ16 -> 0 | AQ2: =AQ3+AQ9+AQ16 -> 1.4000666e+09
C3: COSTO INDIRECTO | O3: =SUM(O4:O8) -> 305200000 | P3: =SUM(P4:P8) -> 0 | Q3: =SUM(Q4:Q8) -> 0 | R3: =SUM(R4:R8) -> 0 | S3: =SUM(S4:S8) -> 1.4189319e+10 | T3: =SUM(T4:T8) -> 1.4494519e+10 | W3: =SUM(W4:W8) -> 305200000 | X3: =SUM(X4:X8) -> 0 | Y3: =SUM(Y4:Y8) -> 0 | Z3: =SUM(Z4:Z8) -> 0 | AA3: =SUM(AA4:AA8) -> 1.298824e+10 | AB3: =SUM(AB4:AB8) -> 1.329344e+10 | AE3: =SUM(AE4:AE8) -> 0 | AF3: =SUM(AF4:AF8) -> 0 | AG3: =SUM(AG4:AG8) -> 0 | AH3: =SUM(AH4:AH8) -> 0 | AI3: =SUM(AI4:AI8) -> 0 | AJ3: =SUM(AJ4:AJ8) -> 0 | AQ3: =SUM(AQ4:AQ8) -> 5.8927538e+08
B4: 1.1 | C4: INSTALACION FAENA | O4: =SUM(O22:O24) -> 0 | P4: =SUM(P22:P24) -> 0 | Q4: =SUM(Q22:Q24) -> 0 | R4: =SUM(R22:R24) -> 0 | S4: =SUM(S22:S24) -> 1.043907e+09 | T4: =SUM(T22:T24) -> 1.043907e+09 | W4: =SUM(W22:W24) -> 0 | X4: =SUM(X22:X24) -> 0 | Y4: =SUM(Y22:Y24) -> 0 | Z4: =SUM(Z22:Z24) -> 0 | AA4: =SUM(AA22:AA24) -> 1.043907e+09 | AB4: =SUM(AB22:AB24) -> 1.043907e+09 | AE4: =SUM(AE22:AE24) -> 0 | AF4: =SUM(AF22:AF24) -> 0 | AG4: =SUM(AG22:AG24) -> 0 | AH4: =SUM(AH22:AH24) -> 0 | AI4: =SUM(AI22:AI24) -> 0 | AJ4: =SUM(AJ22:AJ24) -> 0 | AQ4: =SUM(AQ22:AQ24) -> 5.8927538e+08
B5: 1.2 | C5: MANTENCION DE CAMINO BICHOFITA | O5: =SUM(O26:O33) -> 305200000 | P5: =SUM(P26:P33) -> 0 | Q5: =SUM(Q26:Q33) -> 0 | R5: =SUM(R26:R33) -> 0 | S5: =SUM(S26:S33) -> 0 | T5: =SUM(T26:T33) -> 305200000 | W5: =SUM(W26:W33) -> 305200000 | X5: =SUM(X26:X33) -> 0 | Y5: =SUM(Y26:Y33) -> 0 | Z5: =SUM(Z26:Z33) -> 0 | AA5: =SUM(AA26:AA33) -> 0 | AB5: =SUM(AB26:AB33) -> 305200000 | AE5: =SUM(AE26:AE33) -> 0 | AF5: =SUM(AF26:AF33) -> 0 | AG5: =SUM(AG26:AG33) -> 0 | AH5: =SUM(AH26:AH33) -> 0 | AI5: =SUM(AI26:AI33) -> 0 | AJ5: =SUM(AJ26:AJ33) -> 0 | AQ5: =SUM(AQ26:AQ33) -> 0
B6: 1.3.1 | C6: GASTOS GENERALES | O6: =O35 -> 0 | P6: =P35 -> 0 | Q6: =Q35 -> 0 | R6: =R35 -> 0 | S6: =S35 -> 1.1780358e+10 | T6: =T35 -> 1.1780358e+10 | W6: =W35 -> 0 | X6: =X35 -> 0 | Y6: =Y35 -> 0 | Z6: =Z35 -> 0 | AA6: =AA35 -> 1.1780358e+10 | AB6: =AB35 -> 1.1780358e+10 | AE6: =AE35 -> 0 | AF6: =AF35 -> 0 | AG6: =AG35 -> 0 | AH6: =AH35 -> 0 | AI6: =AI35 -> 0 | AJ6: =AJ35 -> 0 | AQ6: =AQ35 -> 0
B7: 1.3.2 | C7: GASTOS A COSTO EFECTIVO | O7: =O36 -> 0 | P7: =P36 -> 0 | Q7: =Q36 -> 0 | R7: =R36 -> 0 | S7: =S36 -> 160000000 | T7: =T36 -> 160000000 | W7: =W36 -> 0 | X7: =X36 -> 0 | Y7: =Y36 -> 0 | Z7: =Z36 -> 0 | AA7: =AA36 -> 160000000 | AB7: =AB36 -> 160000000 | AE7: =AE36 -> 0 | AF7: =AF36 -> 0 | AG7: =AG36 -> 0 | AH7: =AH36 -> 0 | AI7: =AI36 -> 0 | AJ7: =AJ36 -> 0 | AQ7: =AQ36 -> 0
B8: 4.1 | C8: INCENTIVO TRIMESTRAL | O8: =O731 -> 0 | P8: =P731 -> 0 | Q8: =Q731 -> 0 | R8: =R731 -> 0 | S8: =S731 -> 1205054055 | T8: =T731 -> 1205054055 | W8: =W731 -> 0 | X8: =X731 -> 0 | Y8: =Y731 -> 0 | Z8: =Z731 -> 0 | AA8: =AA731 -> 3975016 | AB8: =AB731 -> 3975016 | AE8: =AE731 -> 0 | AF8: =AF731 -> 0 | AG8: =AG731 -> 0 | AH8: =AH731 -> 0 | AI8: =AI731 -> 0 | AJ8: =AJ731 -> 0 | AQ8: =AQ731 -> 0
C9: COSTO DIRECTO | O9: =SUM(O10:O15) -> 12123676364 | P9: =SUM(P10:P15) -> 1.9221375e+10 | Q9: =SUM(Q10:Q15) -> 2.6323838e+09 | R9: =SUM(R10:R15) -> 4.6030447e+09 | S9: =SUM(S10:S15) -> 0 | T9: =SUM(T10:T15) -> 3.858048e+10 | W9: =SUM(W10:W15) -> 12123676364 | X9: =SUM(X10:X15) -> 1.9221375e+10 | Y9: =SUM(Y10:Y15) -> 2.6323838e+09 | Z9: =SUM(Z10:Z15) -> 4.6030447e+09 | AA9: =SUM(AA10:AA15) -> 0 | AB9: =SUM(AB10:AB15) -> 3.858048e+10 | AE9: =SUM(AE10:AE15) -> 0 | AF9: =SUM(AF10:AF15) -> 0 | AG9: =SUM(AG10:AG15) -> 0 | AH9: =SUM(AH10:AH15) -> 0 | AI9: =SUM(AI10:AI15) -> 0 | AJ9: =SUM(AJ10:AJ15) -> 0 | AQ9: =SUM(AQ10:AQ15) -> 8.1079126e+08
B10: 2.1 | C10: MANEJO RIPIOS | O10: =SUM(O39:O205) -> 1751055083 | P10: =SUM(P39:P205) -> 2.9392104e+09 | Q10: =SUM(Q39:Q205) -> 3.9389245e+08 | R10: =SUM(R39:R205) -> 6.8876907e+08 | S10: =SUM(S39:S205) -> 0 | T10: =SUM(T39:T205) -> 5.772927e+09 | W10: =SUM(W39:W205) -> 1751055083 | X10: =SUM(X39:X205) -> 2.9392104e+09 | Y10: =SUM(Y39:Y205) -> 3.9389245e+08 | Z10: =SUM(Z39:Z205) -> 6.8876907e+08 | AA10: =SUM(AA39:AA205) -> 0 | AB10: =SUM(AB39:AB205) -> 5.772927e+09 | AE10: =SUM(AE39:AE205) -> 0 | AF10: =SUM(AF39:AF205) -> 0 | AG10: =SUM(AG39:AG205) -> 0 | AH10: =SUM(AH39:AH205) -> 0 | AI10: =SUM(AI39:AI205) -> 0 | AJ10: =SUM(AJ39:AJ205) -> 0 | AQ10: =SUM(AQ39:AQ205) -> 0
B11: 2.2 | C11: REGADIO LIXIVIACION SECUNDARIA | O11: =SUM(O206:O352) -> 192553210 | P11: =SUM(P206:P352) -> 3.7086517e+09 | Q11: =SUM(Q206:Q352) -> 3.2762647e+08 | R11: =SUM(R206:R352) -> 5.7289492e+08 | S11: =SUM(S206:S352) -> 0 | T11: =SUM(T206:T352) -> 4.8017263e+09 | W11: =SUM(W206:W352) -> 192553210 | X11: =SUM(X206:X352) -> 3.7086517e+09 | Y11: =SUM(Y206:Y352) -> 3.2762647e+08 | Z11: =SUM(Z206:Z352) -> 5.7289492e+08 | AA11: =SUM(AA206:AA352) -> 0 | AB11: =SUM(AB206:AB352) -> 4.8017263e+09 | AE11: =SUM(AE206:AE352) -> 0 | AF11: =SUM(AF206:AF352) -> 0 | AG11: =SUM(AG206:AG352) -> 0 | AH11: =SUM(AH206:AH352) -> 0 | AI11: =SUM(AI206:AI352) -> 0 | AJ11: =SUM(AJ206:AJ352) -> 0 | AQ11: =SUM(AQ206:AQ352) -> 2.4762178e+08
B12: 2.3 | C12: MANEJO DE SOLUCIONES PLS | O12: =SUM(O353:O513) -> 4603157049 | P12: =SUM(P353:P513) -> 2.5981418e+09 | Q12: =SUM(Q353:Q513) -> 6.0477115e+08 | R12: =SUM(R353:R513) -> 1.0575162e+09 | S12: =SUM(S353:S513) -> 0 | T12: =SUM(T353:T513) -> 8.8635863e+09 | W12: =SUM(W353:W513) -> 4603157049 | X12: =SUM(X353:X513) -> 2.5981418e+09 | Y12: =SUM(Y353:Y513) -> 6.0477115e+08 | Z12: =SUM(Z353:Z513) -> 1.0575162e+09 | AA12: =SUM(AA353:AA513) -> 0 | AB12: =SUM(AB353:AB513) -> 8.8635863e+09 | AE12: =SUM(AE353:AE513) -> 0 | AF12: =SUM(AF353:AF513) -> 0 | AG12: =SUM(AG353:AG513) -> 0 | AH12: =SUM(AH353:AH513) -> 0 | AI12: =SUM(AI353:AI513) -> 0 | AJ12: =SUM(AJ353:AJ513) -> 0 | AQ12: =SUM(AQ353:AQ513) -> 1.938665e+08
B13: 2.4 | C13: CONDUCCION | O13: =SUM(O514:O602) -> 4999459551 | P13: =SUM(P514:P602) -> 1.1536332e+09 | Q13: =SUM(Q514:Q602) -> 5.1674191e+08 | R13: =SUM(R514:R602) -> 9.0358637e+08 | S13: =SUM(S514:S602) -> 0 | T13: =SUM(T514:T602) -> 7.573421e+09 | W13: =SUM(W514:W602) -> 4999459551 | X13: =SUM(X514:X602) -> 1.1536332e+09 | Y13: =SUM(Y514:Y602) -> 5.1674191e+08 | Z13: =SUM(Z514:Z602) -> 9.0358637e+08 | AA13: =SUM(AA514:AA602) -> 0 | AB13: =SUM(AB514:AB602) -> 7.573421e+09 | AE13: =SUM(AE514:AE602) -> 0 | AF13: =SUM(AF514:AF602) -> 0 | AG13: =SUM(AG514:AG602) -> 0 | AH13: =SUM(AH514:AH602) -> 0 | AI13: =SUM(AI514:AI602) -> 0 | AJ13: =SUM(AJ514:AJ602) -> 0 | AQ13: =SUM(AQ514:AQ602) -> 0
